Workbook
Name Brand: Source!$H$3:$H$4
Name Hyundai: Source!$J$3
Name Hyundai_3Phase: Source!$M$3:$M$25
Name TECO: Source!$I$3:$I$4
Name TECO_1Phase: Source!$K$3:$K$10
Name TECO_3Phase: Source!$L$3:$L$25

Sheet Centrifugal Inline Blower
A12: JOB ORDER
A13: JOB ORDER# | B13: : | D13: =Source!B66 -> AFBM-JO2600068a | O13: Date | Q13: : | S13: =Source!B65 -> 46209
C14: __________________________________________ | R14: _________________________________
A15: Project | B15: : | C15: =Source!B70&" "&Source!B71&" "&Source!B77&""" Ø "&Source!B67 | F15: =Source!B70 -> 1 | H15: =Source!B71 -> pc. | J15: =Source!B77 -> 10.5 | L15: " Ø | N15: =Source!B67 -> CIEB | P15: ( | Q15: =" ("&Source!B68&")" | R15: =Source!B68 -> Standard | T15: )
C16: _________________________________________________________________________________________
A17: Target Date: | C17: =Source!B69 -> 46211 | I17: Date Started: | R17: Date Finished:
B18: ____________________ | L18: ____________________ | U18: ____________________
A20: PRODUCTION LEAD TIME | F20: Body | H20: =Source!B72 -> 3 | J20: days | L20: Body | N20: =Source!B73 -> 2 | O20: days
H21: _____ | N21: _____
A36: Orientation | B36: : | C36: =Source!B78 -> Foot Mounted | O36: Impeller | Q36: : | R36: =Source!B80 -> Backwardly Inclined
C37: ___________________________________ | R37: _____________________________
A38: Rotation | B38: : | C38: =Source!B79 -> 12 o'clock facing discharge | O38: Drive | Q38: : | R38: =Source!B81 -> Belt
C39: ___________________________________ | R39: _____________________________
A40: Capacity | B40: : | C40: =Source!B82 | K40: =Source!B83 -> 1238 cfm @ 0" w.g. | M40: =" "&Source!B83
C41: _______________________________________________________________________________
A42: Speed | B42: : | C42: =Source!B84&" rpm" | F42: rpm | I42: =ROUNDUP(Source!D76, 0) -> 2288 | K42: rpm | M42: =" "&ROUNDUP(Source!D76,0)&" rpm"
C43: _______________________________________________________________________________
A44: Drive Motor | B44: : | C44: =Source!D87 -> 3 | D44: HP, | E44: =Source!D88 -> 3 | F44: PH, | G44: =Source!B90 -> 220 | I44: V, | J44: =Source!B91 -> 60 | K44: Hz, | L44: =Source!D90 -> 4 | M44: pole, | N44: =Source!D89 -> 1716 | O44: rpm, | P44: =Source!B92 -> Flange Mounted | T44: , | U44: =Source!B87 -> Hyundai | V44: =Source!B93 -> TEFC
C45: _______________________________________________________________________________
A46: Motor Pulley | B46: : | C46: =TRIM(TEXT(Source!B96,"# ?/?"))&""" Ø x "&Source!D93&" x "&Source!D91&" mm Ø bore x "&Source!D92&" mm keyway" | E46: "Ø x | G46: =Source!D93 -> 2B | I46: x | J46: =Source!D91 -> 28 | K46: mm Ø bore | N46: x | O46: =Source!D92 -> 8 | P46: mm keyway | Q46: =" "&Source!D94&" mm Ø Hub" | U46: =Source!D94 -> 64 | V46: mm Ø Hub
C47: _______________________________________________________________________________
A48: Fan Pulley | B48: : | C48: =TRIM(TEXT(Source!B97,"# ?/?"))&""" Ø x "&Source!D93&" x "&Source!D80 | E48: "Ø x | G48: =Source!D93 -> 2B | I48: x | J48: =Source!D80 -> 1”Ø bore x 5/16" keyway | Q48: =" "&Source!D95&" mm Ø Hub" | U48: =Source!D95 -> 62 | V48: mm Ø Hub
C49: _______________________________________________________________________________
A50: Hub | B50: : | C50: =Source!D79 -> 2” Ø x 2” L x 1"Ø bore x 5/16” keyway
C51: _______________________________________________________________________________
A52: Shafting | B52: : | D52: =Source!D80 -> 1”Ø bore x 5/16" keyway
C53: _______________________________________________________________________________
A54: Belt | B54: :
C55: _______________________________________________________________________________
A56: Bearing | B56: : | C56: =Source!D78&" --" | J56: -- | K56: =SUM(Source!B70)*2 -> 2 | L56: pcs | M56: =" "&SUM(Source!B70)*2&" pcs"
C57: _______________________________________________________________________________
S58: /afbm rev 7 : 03/28/2026

Sheet Source
A2: Centrifugal Blower | H2: Brand | I2: TECO | J2: Hyundai | K2: TECO_1Phase | L2: TECO_3Phase | M2: Hyundai_3Phase | O2: Single Phase, 4 pole, 60Hz, TECO | P2: Single Phase, 4 pole, 60Hz | Q2: RPM | R2: Shaft Diameter | S2: Keyway | T2: HP | U2: Phase | V2: Pole | W2: Pulley
A3: Blade Diameter | B3: Bore Size | C3: Hub Details | D3: Shafting | E3: Bearing | F3: Shaft | H3: TECO | I3: TECO_1Phase | J3: Hyundai_3Phase | K3: 1/4 HP, 1PH, TECO | L3: 1/2 HP, 3PH, TECO | M3: 1/2 HP, 3PH, Hyundai | P3: 1/4 HP, 1PH, TECO | Q3: 1715 | R3: 14 | S3: 5 | T3: 0.25 | U3: 1 | V3: 4 | W3: 1A
A4: 9 | B4: 1”Ø bore x 5/16" keyway | C4: 2” Ø x 2” L x 1"Ø bore x 5/16” keyway | D4: 1"Ø x 5/16” keyway | E4: UCF205 | F4: 1 | H4: Hyundai | I4: TECO_3Phase | K4: 1/2 HP, 1PH, TECO | L4: 1 HP, 3PH, TECO | M4: 1 HP, 3PH, Hyundai | P4: 1/2 HP, 1PH, TECO | Q4: 1750 | R4: 19 | S4: 6 | T4: 0.5 | U4: 1 | V4: 4 | W4: 1A
A5: 10.5 | B5: 1”Ø bore x 5/16" keyway | C5: 2” Ø x 2” L x 1"Ø bore x 5/16” keyway | D5: 1"Ø x 5/16” keyway | E5: UCF205 | F5: 1 | K5: 3 /4 HP, 1PH, TECO | L5: 1 1/2 HP, 3PH, TECO | M5: 1 1/2 HP, 3PH, Hyundai | P5: 3 /4 HP, 1PH, TECO | Q5: 1750 | R5: 19 | S5: 6 | T5: 0.75 | U5: 1 | V5: 4 | W5: 1A
A6: 12.25 | B6: 1 1/4”Ø bore x 3/8" keyway | C6: 2 1/2”Ø x 2 1/2”L x 1 1/4"Ø bore x 3/8” keyway | D6: 1 1/4"Ø x 3/8” keyway | E6: UCF207 | F6: 1.25 | K6: 1 HP, 1PH, TECO | L6: 2 HP, 3PH, TECO | M6: 2 HP, 3PH, Hyundai | P6: 1 HP, 1PH, TECO | Q6: 1750 | R6: 24 | S6: 8 | T6: 1 | U6: 1 | V6: 4 | W6: 1A
A7: 13.5 | B7: 1 1/4”Ø bore x 3/8" keyway | C7: 2 1/2”Ø x 2 1/2”L x 1 1/4"Ø bore x 3/8” keyway | D7: 1 1/4"Ø x 3/8” keyway | E7: UCF207 | F7: 1.25 | K7: 1.5 HP, 1PH, TECO | L7: 3 HP, 3PH, TECO | M7: 3 HP, 3PH, Hyundai | P7: 1.5 HP, 1PH, TECO | Q7: 1750 | R7: 24 | S7: 8 | T7: 1.5 | U7: 1 | V7: 4 | W7: 2B
A8: 15 | B8: 1 1/4”Ø bore x 3/8" keyway | C8: 2 1/2”Ø x 2 1/2”L x 1 1/4"Ø bore x 3/8” keyway | D8: 1 1/4"Ø x 3/8” keyway | E8: UCF207 | F8: 1.25 | K8: 2 HP, 1PH, TECO | L8: 5 HP, 3PH, TECO | M8: 5.5 HP, 3PH, Hyundai | P8: 2 HP, 1PH, TECO | Q8: 1750 | R8: 28 | S8: 8 | T8: 2 | U8: 1 | V8: 4 | W8: 2B
A9: 16.5 | B9: 1 1/4”Ø bore x 3/8" keyway | C9: 2 1/2”Ø x 2 1/2”L x 1 1/4"Ø bore x 3/8” keyway | D9: 1 1/4"Ø x 3/8” keyway | E9: UCF207 | F9: 1.25 | K9: 3 HP, 1PH, TECO | L9: 7 1/2 HP, 3PH, TECO | M9: 7 1/2 HP, 3PH, Hyundai | P9: 3 HP, 1PH, TECO | Q9: 1750 | R9: 28 | S9: 8 | T9: 3 | U9: 1 | V9: 4 | W9: 2B
A10: 18.25 | B10: 1 1/4”Ø bore x 3/8" keyway | C10: 2 1/2”Ø x 2 1/2”L x 1 1/4"Ø bore x 3/8” keyway | D10: 1 1/4"Ø x 3/8” keyway | E10: UCF207 | F10: 1.25 | K10: 5 HP, 1PH, TECO | L10: 10 HP, 3PH, TECO | M10: 10 HP, 3PH, Hyundai | P10: 5 HP, 1PH, TECO | Q10: 1750 | R10: 28 | S10: 8 | T10: 5 | U10: 1 | V10: 4 | W10: 2B
A11: 20 | B11: 1 1/4”Ø bore x 3/8" keyway | C11: 2 1/2”Ø x 2 1/2”L x 1 1/4"Ø bore x 3/8” keyway | D11: 1 1/4"Ø x 3/8” keyway | E11: UCF207 | F11: 1.25 | L11: 15 HP, 3PH, TECO | M11: 15 HP, 3PH, Hyundai | O11: Three Phase, 4 pole, 60Hz, TECO | P11: 1/2 HP, 3PH, TECO | Q11: 1680 | R11: 14 | S11: 5 | T11: 0.5 | U11: 3 | V11: 4 | W11: 1A
A12: 22.25 | B12: 1 1/4”Ø bore x 3/8" keyway | C12: 2 1/2”Ø x 2 1/2”L x 1 1/4"Ø bore x 3/8” keyway | D12: 1 1/4"Ø x 3/8” keyway | E12: UCF207 | F12: 1.25 | L12: 20 HP, 3PH, TECO | M12: 20 HP, 3PH, Hyundai | P12: 1 HP, 3PH, TECO | Q12: 1710 | R12: 19 | S12: 6 | T12: 1 | U12: 3 | V12: 4 | W12: 2A
A13: 24.5 | B13: 1 1/2”Ø bore x 3/8" keyway | C13: 3”Ø x 3”L x 1 1/2”Ø bore x 3/8” keyway | D13: 1 1/2”Ø x 3/8” keyway | E13: UCF208 | F13: 1.5 | L13: 25 HP, 3PH, TECO | M13: 25 HP, 3PH, Hyundai | P13: 1 1/2 HP, 3PH, TECO | Q13: 1720 | R13: 24 | S13: 8 | T13: 1.5 | U13: 3 | V13: 4 | W13: 2B
A14: 27 | B14: 1 1/2”Ø bore x 3/8" keyway | C14: 3”Ø x 3”L x 1 1/2”Ø bore x 3/8” keyway | D14: 1 1/2”Ø x 3/8” keyway | E14: UCP208 | F14: 1.5 | L14: 30 HP, 3PH, TECO | M14: 30 HP, 3PH, Hyundai | P14: 2 HP, 3PH, TECO | Q14: 1715 | R14: 24 | S14: 8 | T14: 2 | U14: 3 | V14: 4 | W14: 2B
A15: 30 | B15: 1 3/4”Ø bore x 1/2" keyway | C15: 3 1/2” Ø x 3 1/2” L x 1 3/4"Ø bore x 1/2” keyway | D15: 1 3/4 x 1/2” keyway | E15: UCP209 | F15: 1.75 | L15: 40 HP, 3PH, TECO | M15: 40 HP, 3PH, Hyundai | P15: 3 HP, 3PH, TECO | Q15: 1735 | R15: 28 | S15: 8 | T15: 3 | U15: 3 | V15: 4 | W15: 2B
A16: 33 | B16: 2”Ø bore x 1/2" keyway | C16: 4”Ø x 4”L x 2"Ø bore x 1/2” keyway | D16: 2"Ø x 1/2” keyway | E16: UCP211 | F16: 2 | L16: 50 HP, 3PH, TECO | M16: 50 HP, 3PH, Hyundai | P16: 5 HP, 3PH, TECO | Q16: 1745 | R16: 28 | S16: 8 | T16: 5 | U16: 3 | V16: 4 | W16: 2B
A17: 36.5 | B17: 2”Ø bore x 1/2" keyway | C17: 4”Ø x 4”L x 2"Ø bore x 1/2” keyway | D17: 2"Ø x 1/2” keyway | E17: UCP211 | F17: 2 | L17: 60 HP, 3PH, TECO | M17: 60 HP, 3PH, Hyundai | P17: 7 1/2 HP, 3PH, TECO | Q17: 1750 | R17: 38 | S17: 10 | T17: 7.5 | U17: 3 | V17: 4 | W17: 2B
A18: 40.25 | B18: 2 1/4”Ø x 1/2" keyway | C18: 4”Ø x 4”L x 2 1/4"Ø bore x 1/2” keyway | D18: 2 1/4”Ø x 1/2" keyway | E18: UCP212 | F18: 2.25 | L18: 75 HP, 3PH, TECO | M18: 75 HP, 3PH, Hyundai | P18: 10 HP, 3PH, TECO | Q18: 1750 | R18: 38 | S18: 10 | T18: 10 | U18: 3 | V18: 4 | W18: 3B
A19: 44.5 | B19: 2 1/4”Ø x 1/2" keyway | C19: 4”Ø x 4”L x 2 1/4"Ø bore x 1/2” keyway | D19: 2 1/4”Ø x 1/2" keyway | E19: UCP212 | F19: 2.25 | L19: 100 HP, 3PH, TECO | M19: 100 HP, 3PH, Hyundai | P19: 15 HP, 3PH, TECO | Q19: 1760 | R19: 42 | S19: 12 | T19: 15 | U19: 3 | V19: 4 | W19: 3B
A20: 49 | B20: 2 1/2”Ø x 1/2" keyway | C20: 4 1/2”Ø x 4 1/2”L x 2 1/2"Ø bore x 1/2” keyway | D20: 2 1/2"Ø x 1/2” keyway | E20: UCP213 | F20: 2.5 | L20: 125 HP, 3PH, TECO | M20: 125 HP, 3PH, Hyundai | P20: 20 HP, 3PH, TECO | Q20: 1760 | R20: 42 | S20: 12 | T20: 20 | U20: 3 | V20: 4 | W20: 3C
A21: 54.5 | B21: 2 1/2”Ø x 1/2" keyway | C21: 4 1/2”Ø x 4 1/2”L x 2 1/2"Ø bore x 1/2” keyway | D21: 2 1/2"Ø x 1/2” keyway | E21: UCP213 | F21: 2.5 | L21: 150 HP, 3PH, TECO | M21: 150 HP, 3PH, Hyundai | P21: 25 HP, 3PH, TECO | Q21: 1760 | R21: 48 | S21: 14 | T21: 25 | U21: 3 | V21: 4 | W21: 3C
A22: 60 | B22: 3”Ø x 1/2" keyway | C22: 5”Ø x 5”L x 3"Ø bore x 1/2” keyway | D22: 3"Ø x 1/2” keyway | E22: UCP215 | F22: 3 | L22: 175 HP, 3PH, TECO | M22: 180 HP, 3PH, Hyundai | P22: 30 HP, 3PH, TECO | Q22: 1765 | R22: 48 | S22: 14 | T22: 30 | U22: 3 | V22: 4 | W22: 4C
A23: 66 | B23: 3”Ø x 1/2" keyway | C23: 5”Ø x 5”L x 3"Ø bore x 1/2” keyway | D23: 3"Ø x 1/2” keyway | E23: UCP215 | F23: 3 | L23: 200 HP, 3PH, TECO | M23: 200 HP, 3PH, Hyundai | P23: 40 HP, 3PH, TECO | Q23: 1760 | R23: 55 | S23: 16 | T23: 40 | U23: 3 | V23: 4 | W23: 5C
... A25: 83 | B25: 3”Ø x 1/2" keyway | C25: 5”Ø x 5”L x 3"Ø bore x 1/2” keyway | D25: 3"Ø x 1/2” keyway | E25: UCP215 | F25: 3 | L25: 300 HP, 3PH, TECO | M25: 340 HP, 3PH, Hyundai | P25: 60 HP, 3PH, TECO | Q25: 1765 | R25: 60 | S25: 18 | T25: 60 | U25: 3 | V25: 4 | W25: 6C
P26: 75 HP, 3PH, TECO | Q26: 1775 | R26: 65 | S26: 18 | T26: 75 | U26: 3 | V26: 4 | W26: 6C
P27: 100 HP, 3PH, TECO | Q27: 1775 | R27: 75 | S27: 20 | T27: 100 | U27: 3 | V27: 4 | W27: 6C
A28: Impeller | B28: Make | P28: 125 HP, 3PH, TECO | Q28: 1770 | R28: 75 | S28: 20 | T28: 125 | U28: 3 | V28: 4 | W28: 6C
A29: Backwardly Inclined | B29: Standard | P29: 150 HP, 3PH, TECO | Q29: 1770 | R29: 85 | S29: 22 | T29: 150 | U29: 3 | V29: 4 | W29: 6C
A30: Backward Curved | B30: Customized | P30: 175 HP, 3PH, TECO | Q30: 1770 | R30: 85 | S30: 22 | T30: 175 | U30: 3 | V30: 4 | W30: 6C
A31: Airfoil | B31: Client Design | P31: 200 HP, 3PH, TECO | Q31: 1775 | R31: 95 | S31: 25 | T31: 200 | U31: 3 | V31: 4 | W31: 6C
P32: 250 HP, 3PH, TECO | Q32: 1775 | R32: 95 | S32: 25 | T32: 250 | U32: 3 | V32: 4 | W32: 6C
P33: 300 HP, 3PH, TECO | Q33: 1775 | R33: 95 | S33: 25 | T33: 300 | U33: 3 | V33: 4 | W33: 6C
A34: Drive | O34: Three Phase, 4 pole, 60Hz, Hyundai | P34: 1/2 HP, 3PH, Hyundai | Q34: 1660 | R34: 14 | S34: 5 | T34: 0.5 | U34: 3 | V34: 4 | W34: 1A
A35: Direct | P35: 1 HP, 3PH, Hyundai | Q35: 1668 | R35: 19 | S35: 6 | T35: 1 | U35: 3 | V35: 4 | W35: 2A
A36: Belt | P36: 1 1/2 HP, 3PH, Hyundai | Q36: 1680 | R36: 24 | S36: 8 | T36: 1.5 | U36: 3 | V36: 4 | W36: 2B
A37: Directly Coupled | P37: 2 HP, 3PH, Hyundai | Q37: 1680 | R37: 24 | S37: 8 | T37: 2 | U37: 3 | V37: 4 | W37: 2B
P38: 3 HP, 3PH, Hyundai | Q38: 1716 | R38: 28 | S38: 8 | T38: 3 | U38: 3 | V38: 4 | W38: 2B
P39: 5.5 HP, 3PH, Hyundai | Q39: 1728 | R39: 28 | S39: 8 | T39: 5.5 | U39: 3 | V39: 4 | W39: 2B
A40: Motor Phase | B40: Voltage | C40: Frequency | D40: Pole | E40: Mounting | F40: Enclosure | P40: 7 1/2 HP, 3PH, Hyundai | Q40: 1728 | R40: 38 | S40: 10 | T40: 7.5 | U40: 3 | V40: 4 | W40: 2B
A41: 1 | B41: 220 | C41: 60 | D41: 2 | E41: Foot Mounted | F41: TEFC | P41: 10 HP, 3PH, Hyundai | Q41: 1728 | R41: 38 | S41: 10 | T41: 10 | U41: 3 | V41: 4 | W41: 3B
A42: 3 | B42: 380 | C42: 50 | D42: 4 | E42: Flange Mounted | F42: Exproof | P42: 15 HP, 3PH, Hyundai | Q42: 1728 | R42: 42 | S42: 12 | T42: 15 | U42: 3 | V42: 4 | W42: 3B
...
